<?xml version="1.0" ?>
<robot name="flying-wing">
  <material name="industrial-blue">
    <color rgba="0.11372549019607843 0.34509803921568627 0.6549019607843137 1.0"/>
  </material>
  <material name="arches-blue">
    <color rgba="0.0 0.6235294117647059 0.8313725490196079 1.0"/>
  </material>
  <material name="heritage-orange">
    <color rgba="0.96078431 0.50980392 0.11764706 1.0"/>
  </material>

  <link name="base">
    <visual>
      <geometry>
        <mesh filename="Rocket_Body.stl">
          <scale x="0.1" y="0.1" z="0.1"/>
        </mesh>
      </geometry>
      <material name="industrial-blue"/>
    </visual>
    <collision>
      <geometry>
        <mesh filename="Rocket_Body.stl">
          <scale x="0.1" y="0.1" z="0.1"/>
        </mesh>
      </geometry>
    </collision>
    <inertial>
      <origin rpy="0.0 0.0 0.0" xyz="0.0 0.0 0.0"/>
      <mass value="1.56"/>
      <inertia ixx="0.1147" ixy="0.0" ixz="0.0015" iyy="0.0576" iyz="0.0" izz="0.1712"/>
    </inertial>
  </link>

  <!-- Right Aileron -->
  <link name="aileron_right">
    <visual>
      <origin xyz="0.5 -0.3 0.0" rpy="0 0 0"/> <!-- Adjust xyz to actual location -->
      <geometry>
        <mesh filename="Aileron.stl"/>
      </geometry>
      <material name="heritage-orange"/>
    </visual>
    <collision>
      <origin xyz="0.5 -0.3 0.0" rpy="0 0 0"/>
      <geometry>
        <mesh filename="Aileron.stl"/>
      </geometry>
    </collision>
    <inertial>
      <origin xyz="0 0 0" rpy="0 0 0"/>
      <mass value="0.05"/>
      <inertia ixx="0.0001" ixy="0.0" ixz="0.0" iyy="0.0001" iyz="0.0" izz="0.0001"/>
    </inertial>
  </link>

  <joint name="right_aileron_joint" type="revolute">
    <parent link="base"/>
    <child link="aileron_right"/>
    <origin xyz="0.5 -0.3 0.0" rpy="0 0 0"/> <!-- Same as aileron_right origin -->
    <axis xyz="0 1 0"/> <!-- Adjust axis as needed (here, rotate about y) -->
    <limit lower="-0.5" upper="0.5" effort="1" velocity="1"/>
  </joint>

  <!-- Left Aileron -->
  <link name="aileron_left">
    <visual>
      <origin xyz="0 0 0" rpy="0 0 3.1416"/> <!-- Adjust xyz to actual location -->
      <geometry>
        <mesh filename="Aileron.stl"/>
      </geometry>
      <material name="heritage-orange"/>
    </visual>
    <collision>
      <origin xyz="0 0 0" rpy="0 0 3.1416"/>
      <geometry>
        <mesh filename="Aileron.stl"/>
      </geometry>
    </collision>
    <inertial>
      <origin xyz="0 0 0" rpy="0 0 0"/>
      <mass value="0.05"/>
      <inertia ixx="0.0001" ixy="0.0" ixz="0.0" iyy="0.0001" iyz="0.0" izz="0.0001"/>
    </inertial>
  </link>

  <joint name="left_aileron_joint" type="revolute">
    <parent link="base"/>
    <child link="aileron_left"/>
    <origin xyz="0 0 0" rpy="0 0 3.1416"/> <!-- Same as aileron_left origin -->
    <axis xyz="0 1 0"/> <!-- Adjust axis as needed (here, rotate about y) -->
    <limit lower="-0.5" upper="0.5" effort="1" velocity="1"/>
  </joint>
</robot>
